Workbook

Sheet Instructions
A1: PV Case Query & MedDRA Coding Analytics Dashboard
A2: A portfolio project simulating case query management and MedDRA coding analytics for a Pharmacovigilance team
A4: PURPOSE
A5: This workbook simulates how a Pharmacovigilance (PV) Associate or Analyst tracks Individual Case Safety Reports (ICSRs) through intake, MedDRA coding, data-management queries, and expedited regulatory reporting timelines. It is built on synthetic data for portfolio and interview demonstration purposes only.
A7: SHEETS
A8: Raw Data - 400 synthetic ICSR-style case records with MedDRA System Organ Class (SOC) and Preferred Term (PT) coding, seriousness classification, query status, and submission timelines.
A9: Dashboard - KPI summary cards and six analytics views built entirely from live formulas (COUNTIFS, SUMIFS, AVERAGEIF) referencing Raw Data, plus charts. Everything recalculates if Raw Data changes.
A11: KEY PV CONCEPTS DEMONSTRATED
A12: MedDRA coding distribution - which System Organ Classes and Preferred Terms occur most often, which is what a coder/reviewer monitors for consistency and signal patterns.
A13: Query turnaround time - the operational KPI CROs track for data management query cycle time (query raised to query closed).
A14: Query backlog aging - how many queries are still open, bucketed by age, which is a standard PV/CDM team workload metric.
A15: Expedited reporting timeliness - percentage of Serious cases submitted within the assumed regulatory deadline, referencing ICH E2A/E2D-style expedited timelines.
... A23: Open the Dashboard tab and walk through the KPI cards first (case volume, seriousness mix, query turnaround, on-time submission rate), then use the SOC and query-type charts to talk through how coding and query patterns would inform process improvements on a real study.

Sheet Raw Data
A1: Case_ID | B1: Receipt_Date | C1: Product | D1: MedDRA_SOC | E1: MedDRA_PT | F1: Seriousness | G1: Country | H1: Reporter_Type | I1: Query_Raised | J1: Query_Type | K1: Query_Open_Date | L1: Query_Close_Date | M1: Days_to_Close | N1: Submission_Date | O1: Regulatory_Deadline_Days | P1: Days_to_Submission | Q1: Submitted_On_Time | R1: Open_Query_Age_Days
A2: PV-2026-0001 | B2: 45772 | C2: CardioStat | D2: Cardiac disorders | E2: Tachycardia | F2: Serious | G2: Brazil | H2: Consumer | I2: No | M2: =IF(AND(K2<>"",L2<>""),L2-K2,"") | N2: 45780 | O2: =IF(F2="Serious",15,"N/A") -> 15 | P2: =N2-B2 -> 8 | Q2: =IF(F2="Serious",IF(P2<=O2,"Yes","No"),"N/A") -> Yes | R2: =IF(AND(I2="Yes",L2=""),Dashboard!$B$2-K2,"")
A3: PV-2026-0002 | B3: 45690 | C3: CardioStat | D3: Skin and subcutaneous tissue disorders | E3: Rash | F3: Serious | G3: UK | H3: Consumer | I3: No | M3: =IF(AND(K3<>"",L3<>""),L3-K3,"") | N3: 45698 | O3: =IF(F3="Serious",15,"N/A") -> 15 | P3: =N3-B3 -> 8 | Q3: =IF(F3="Serious",IF(P3<=O3,"Yes","No"),"N/A") -> Yes | R3: =IF(AND(I3="Yes",L3=""),Dashboard!$B$2-K3,"")
A4: PV-2026-0003 | B4: 45883 | C4: ImmunoShield | D4: Renal and urinary disorders | E4: Renal impairment | F4: Non-serious | G4: India | H4: Pharmacist | I4: No | M4: =IF(AND(K4<>"",L4<>""),L4-K4,"") | N4: 45909 | O4: =IF(F4="Serious",15,"N/A") -> N/A | P4: =N4-B4 -> 26 | Q4: =IF(F4="Serious",IF(P4<=O4,"Yes","No"),"N/A") -> N/A | R4: =IF(AND(I4="Yes",L4=""),Dashboard!$B$2-K4,"")
A5: PV-2026-0004 | B5: 45942 | C5: DiabeCare | D5: Immune system disorders | E5: Anaphylactic reaction | F5: Serious | G5: USA | H5: Healthcare Professional | I5: Yes | J5: MedDRA Coding Query | K5: 45943 | L5: 45960 | M5: =IF(AND(K5<>"",L5<>""),L5-K5,"") -> 17 | N5: 45964 | O5: =IF(F5="Serious",15,"N/A") -> 15 | P5: =N5-B5 -> 22 | Q5: =IF(F5="Serious",IF(P5<=O5,"Yes","No"),"N/A") -> No | R5: =IF(AND(I5="Yes",L5=""),Dashboard!$B$2-K5,"")
A6: PV-2026-0005 | B6: 45738 | C6: OncoRelief | D6: Cardiac disorders | E6: Palpitations | F6: Non-serious | G6: Germany | H6: Healthcare Professional | I6: Yes | J6: MedDRA Coding Query | K6: 45740 | M6: =IF(AND(K6<>"",L6<>""),L6-K6,"") | N6: 45798 | O6: =IF(F6="Serious",15,"N/A") -> N/A | P6: =N6-B6 -> 60 | Q6: =IF(F6="Serious",IF(P6<=O6,"Yes","No"),"N/A") -> N/A | R6: =IF(AND(I6="Yes",L6=""),Dashboard!$B$2-K6,"") -> 474
A7: PV-2026-0006 | B7: 45761 | C7: ImmunoShield | D7: Cardiac disorders | E7: Palpitations | F7: Non-serious | G7: USA | H7: Healthcare Professional | I7: Yes | J7: MedDRA Coding Query | K7: 45763 | L7: 45771 | M7: =IF(AND(K7<>"",L7<>""),L7-K7,"") -> 8 | N7: 45812 | O7: =IF(F7="Serious",15,"N/A") -> N/A | P7: =N7-B7 -> 51 | Q7: =IF(F7="Serious",IF(P7<=O7,"Yes","No"),"N/A") -> N/A | R7: =IF(AND(I7="Yes",L7=""),Dashboard!$B$2-K7,"")
A8: PV-2026-0007 | B8: 45908 | C8: DiabeCare | D8: Investigations | E8: Liver function test abnormal | F8: Non-serious | G8: Canada | H8: Consumer | I8: Yes | J8: MedDRA Coding Query | K8: 45909 | L8: 45913 | M8: =IF(AND(K8<>"",L8<>""),L8-K8,"") -> 4 | N8: 45933 | O8: =IF(F8="Serious",15,"N/A") -> N/A | P8: =N8-B8 -> 25 | Q8: =IF(F8="Serious",IF(P8<=O8,"Yes","No"),"N/A") -> N/A | R8: =IF(AND(I8="Yes",L8=""),Dashboard!$B$2-K8,"")
A9: PV-2026-0008 | B9: 46068 | C9: NeuroCalm | D9: Skin and subcutaneous tissue disorders | E9: Rash | F9: Non-serious | G9: UK | H9: Consumer | I9: Yes | J9: Causality Assessment | K9: 46075 | M9: =IF(AND(K9<>"",L9<>""),L9-K9,"") | N9: 46114 | O9: =IF(F9="Serious",15,"N/A") -> N/A | P9: =N9-B9 -> 46 | Q9: =IF(F9="Serious",IF(P9<=O9,"Yes","No"),"N/A") -> N/A | R9: =IF(AND(I9="Yes",L9=""),Dashboard!$B$2-K9,"") -> 139
A10: PV-2026-0009 | B10: 46127 | C10: DiabeCare | D10: Cardiac disorders | E10: Tachycardia | F10: Serious | G10: UK | H10: Healthcare Professional | I10: Yes | J10: Follow-up Required | K10: 46134 | L10: 46176 | M10: =IF(AND(K10<>"",L10<>""),L10-K10,"") -> 42 | N10: 46136 | O10: =IF(F10="Serious",15,"N/A") -> 15 | P10: =N10-B10 -> 9 | Q10: =IF(F10="Serious",IF(P10<=O10,"Yes","No"),"N/A") -> Yes | R10: =IF(AND(I10="Yes",L10=""),Dashboard!$B$2-K10,"")
A11: PV-2026-0010 | B11: 45751 | C11: CardioStat | D11: Skin and subcutaneous tissue disorders | E11: Rash | F11: Non-serious | G11: Brazil | H11: Healthcare Professional | I11: Yes | J11: Causality Assessment | K11: 45761 | M11: =IF(AND(K11<>"",L11<>""),L11-K11,"") | N11: 45789 | O11: =IF(F11="Serious",15,"N/A") -> N/A | P11: =N11-B11 -> 38 | Q11: =IF(F11="Serious",IF(P11<=O11,"Yes","No"),"N/A") -> N/A | R11: =IF(AND(I11="Yes",L11=""),Dashboard!$B$2-K11,"") -> 453
A12: PV-2026-0011 | B12: 45915 | C12: OncoRelief | D12: Gastrointestinal disorders | E12: Nausea | F12: Non-serious | G12: UK | H12: Healthcare Professional | I12: No | M12: =IF(AND(K12<>"",L12<>""),L12-K12,"") | N12: 45927 | O12: =IF(F12="Serious",15,"N/A") -> N/A | P12: =N12-B12 -> 12 | Q12: =IF(F12="Serious",IF(P12<=O12,"Yes","No"),"N/A") -> N/A | R12: =IF(AND(I12="Yes",L12=""),Dashboard!$B$2-K12,"")
A13: PV-2026-0012 | B13: 45958 | C13: ImmunoShield | D13: Nervous system disorders | E13: Dizziness | F13: Serious | G13: Brazil | H13: Consumer | I13: No | M13: =IF(AND(K13<>"",L13<>""),L13-K13,"") | N13: 45968 | O13: =IF(F13="Serious",15,"N/A") -> 15 | P13: =N13-B13 -> 10 | Q13: =IF(F13="Serious",IF(P13<=O13,"Yes","No"),"N/A") -> Yes | R13: =IF(AND(I13="Yes",L13=""),Dashboard!$B$2-K13,"")
A14: PV-2026-0013 | B14: 45766 | C14: NeuroCalm | D14: Psychiatric disorders | E14: Insomnia | F14: Serious | G14: Brazil | H14: Consumer | I14: No | M14: =IF(AND(K14<>"",L14<>""),L14-K14,"") | N14: 45768 | O14: =IF(F14="Serious",15,"N/A") -> 15 | P14: =N14-B14 -> 2 | Q14: =IF(F14="Serious",IF(P14<=O14,"Yes","No"),"N/A") -> Yes | R14: =IF(AND(I14="Yes",L14=""),Dashboard!$B$2-K14,"")
A15: PV-2026-0014 | B15: 45989 | C15: ImmunoShield | D15: Gastrointestinal disorders | E15: Nausea | F15: Non-serious | G15: Japan | H15: Pharmacist | I15: Yes | J15: Missing Information | K15: 45993 | M15: =IF(AND(K15<>"",L15<>""),L15-K15,"") | N15: 45999 | O15: =IF(F15="Serious",15,"N/A") -> N/A | P15: =N15-B15 -> 10 | Q15: =IF(F15="Serious",IF(P15<=O15,"Yes","No"),"N/A") -> N/A | R15: =IF(AND(I15="Yes",L15=""),Dashboard!$B$2-K15,"") -> 221
A16: PV-2026-0015 | B16: 45745 | C16: ImmunoShield | D16: Skin and subcutaneous tissue disorders | E16: Urticaria | F16: Non-serious | G16: India | H16: Consumer | I16: Yes | J16: MedDRA Coding Query | K16: 45754 | M16: =IF(AND(K16<>"",L16<>""),L16-K16,"") | N16: 45777 | O16: =IF(F16="Serious",15,"N/A") -> N/A | P16: =N16-B16 -> 32 | Q16: =IF(F16="Serious",IF(P16<=O16,"Yes","No"),"N/A") -> N/A | R16: =IF(AND(I16="Yes",L16=""),Dashboard!$B$2-K16,"") -> 460
A17: PV-2026-0016 | B17: 45874 | C17: OncoRelief | D17: Immune system disorders | E17: Anaphylactic reaction | F17: Non-serious | G17: Germany | H17: Healthcare Professional | I17: No | M17: =IF(AND(K17<>"",L17<>""),L17-K17,"") | N17: 45907 | O17: =IF(F17="Serious",15,"N/A") -> N/A | P17: =N17-B17 -> 33 | Q17: =IF(F17="Serious",IF(P17<=O17,"Yes","No"),"N/A") -> N/A | R17: =IF(AND(I17="Yes",L17=""),Dashboard!$B$2-K17,"")
A18: PV-2026-0017 | B18: 45781 | C18: DiabeCare | D18: Immune system disorders | E18: Hypersensitivity | F18: Non-serious | G18: UK | H18: Healthcare Professional | I18: Yes | J18: Missing Information | K18: 45782 | L18: 45814 | M18: =IF(AND(K18<>"",L18<>""),L18-K18,"") -> 32 | N18: 45841 | O18: =IF(F18="Serious",15,"N/A") -> N/A | P18: =N18-B18 -> 60 | Q18: =IF(F18="Serious",IF(P18<=O18,"Yes","No"),"N/A") -> N/A | R18: =IF(AND(I18="Yes",L18=""),Dashboard!$B$2-K18,"")
A19: PV-2026-0018 | B19: 45996 | C19: CardioStat | D19: Psychiatric disorders | E19: Insomnia | F19: Non-serious | G19: USA | H19: Consumer | I19: No | M19: =IF(AND(K19<>"",L19<>""),L19-K19,"") | N19: 46037 | O19: =IF(F19="Serious",15,"N/A") -> N/A | P19: =N19-B19 -> 41 | Q19: =IF(F19="Serious",IF(P19<=O19,"Yes","No"),"N/A") -> N/A | R19: =IF(AND(I19="Yes",L19=""),Dashboard!$B$2-K19,"")
A20: PV-2026-0019 | B20: 46142 | C20: DiabeCare | D20: Investigations | E20: Liver function test abnormal | F20: Serious | G20: India | H20: Healthcare Professional | I20: Yes | J20: Causality Assessment | K20: 46143 | L20: 46182 | M20: =IF(AND(K20<>"",L20<>""),L20-K20,"") -> 39 | N20: 46150 | O20: =IF(F20="Serious",15,"N/A") -> 15 | P20: =N20-B20 -> 8 | Q20: =IF(F20="Serious",IF(P20<=O20,"Yes","No"),"N/A") -> Yes | R20: =IF(AND(I20="Yes",L20=""),Dashboard!$B$2-K20,"")
A21: PV-2026-0020 | B21: 46005 | C21: CardioStat | D21: Immune system disorders | E21: Hypersensitivity | F21: Serious | G21: USA | H21: Healthcare Professional | I21: Yes | J21: Data Inconsistency | K21: 46007 | L21: 46036 | M21: =IF(AND(K21<>"",L21<>""),L21-K21,"") -> 29 | N21: 46007 | O21: =IF(F21="Serious",15,"N/A") -> 15 | P21: =N21-B21 -> 2 | Q21: =IF(F21="Serious",IF(P21<=O21,"Yes","No"),"N/A") -> Yes | R21: =IF(AND(I21="Yes",L21=""),Dashboard!$B$2-K21,"")
A22: PV-2026-0021 | B22: 45673 | C22: CardioStat | D22: Immune system disorders | E22: Hypersensitivity | F22: Non-serious | G22: USA | H22: Pharmacist | I22: No | M22: =IF(AND(K22<>"",L22<>""),L22-K22,"") | N22: 45688 | O22: =IF(F22="Serious",15,"N/A") -> N/A | P22: =N22-B22 -> 15 | Q22: =IF(F22="Serious",IF(P22<=O22,"Yes","No"),"N/A") -> N/A | R22: =IF(AND(I22="Yes",L22=""),Dashboard!$B$2-K22,"")
A23: PV-2026-0022 | B23: 46046 | C23: CardioStat | D23: General disorders and administration site conditions | E23: Fatigue | F23: Non-serious | G23: Brazil | H23: Healthcare Professional | I23: No | M23: =IF(AND(K23<>"",L23<>""),L23-K23,"") | N23: 46097 | O23: =IF(F23="Serious",15,"N/A") -> N/A | P23: =N23-B23 -> 51 | Q23: =IF(F23="Serious",IF(P23<=O23,"Yes","No"),"N/A") -> N/A | R23: =IF(AND(I23="Yes",L23=""),Dashboard!$B$2-K23,"")
A24: PV-2026-0023 | B24: 46156 | C24: DiabeCare | D24: Immune system disorders | E24: Anaphylactic reaction | F24: Serious | G24: India | H24: Consumer | I24: Yes | J24: MedDRA Coding Query | K24: 46157 | L24: 46172 | M24: =IF(AND(K24<>"",L24<>""),L24-K24,"") -> 15 | N24: 46180 | O24: =IF(F24="Serious",15,"N/A") -> 15 | P24: =N24-B24 -> 24 | Q24: =IF(F24="Serious",IF(P24<=O24,"Yes","No"),"N/A") -> No | R24: =IF(AND(I24="Yes",L24=""),Dashboard!$B$2-K24,"")
A25: PV-2026-0024 | B25: 45819 | C25: CardioStat | D25: Psychiatric disorders | E25: Insomnia | F25: Non-serious | G25: India | H25: Healthcare Professional | I25: No | M25: =IF(AND(K25<>"",L25<>""),L25-K25,"") | N25: 45849 | O25: =IF(F25="Serious",15,"N/A") -> N/A | P25: =N25-B25 -> 30 | Q25: =IF(F25="Serious",IF(P25<=O25,"Yes","No"),"N/A") -> N/A | R25: =IF(AND(I25="Yes",L25=""),Dashboard!$B$2-K25,"")
A26: PV-2026-0025 | B26: 45780 | C26: OncoRelief | D26: Immune system disorders | E26: Hypersensitivity | F26: Non-serious | G26: USA | H26: Consumer | I26: Yes | J26: MedDRA Coding Query | K26: 45784 | L26: 45795 | M26: =IF(AND(K26<>"",L26<>""),L26-K26,"") -> 11 | N26: 45801 | O26: =IF(F26="Serious",15,"N/A") -> N/A | P26: =N26-B26 -> 21 | Q26: =IF(F26="Serious",IF(P26<=O26,"Yes","No"),"N/A") -> N/A | R26: =IF(AND(I26="Yes",L26=""),Dashboard!$B$2-K26,"")
A27: PV-2026-0026 | B27: 46063 | C27: DiabeCare | D27: Cardiac disorders | E27: Palpitations | F27: Non-serious | G27: Brazil | H27: Healthcare Professional | I27: Yes | J27: Follow-up Required | K27: 46065 | L27: 46074 | M27: =IF(AND(K27<>"",L27<>""),L27-K27,"") -> 9 | N27: 46084 | O27: =IF(F27="Serious",15,"N/A") -> N/A | P27: =N27-B27 -> 21 | Q27: =IF(F27="Serious",IF(P27<=O27,"Yes","No"),"N/A") -> N/A | R27: =IF(AND(I27="Yes",L27=""),Dashboard!$B$2-K27,"")
A28: PV-2026-0027 | B28: 45793 | C28: NeuroCalm | D28: Skin and subcutaneous tissue disorders | E28: Rash | F28: Non-serious | G28: India | H28: Pharmacist | I28: No | M28: =IF(AND(K28<>"",L28<>""),L28-K28,"") | N28: 45837 | O28: =IF(F28="Serious",15,"N/A") -> N/A | P28: =N28-B28 -> 44 | Q28: =IF(F28="Serious",IF(P28<=O28,"Yes","No"),"N/A") -> N/A | R28: =IF(AND(I28="Yes",L28=""),Dashboard!$B$2-K28,"")
A29: PV-2026-0028 | B29: 46199 | C29: CardioStat | D29: Psychiatric disorders | E29: Anxiety | F29: Non-serious | G29: India | H29: Pharmacist | I29: Yes | J29: Missing Information | K29: 46208 | M29: =IF(AND(K29<>"",L29<>""),L29-K29,"") | N29: 46217 | O29: =IF(F29="Serious",15,"N/A") -> N/A | P29: =N29-B29 -> 18 | Q29: =IF(F29="Serious",IF(P29<=O29,"Yes","No"),"N/A") -> N/A | R29: =IF(AND(I29="Yes",L29=""),Dashboard!$B$2-K29,"") -> 6
A30: PV-2026-0029 | B30: 46009 | C30: DiabeCare | D30: Cardiac disorders | E30: Palpitations | F30: Non-serious | G30: Canada | H30: Healthcare Professional | I30: No | M30: =IF(AND(K30<>"",L30<>""),L30-K30,"") | N30: 46067 | O30: =IF(F30="Serious",15,"N/A") -> N/A | P30: =N30-B30 -> 58 | Q30: =IF(F30="Serious",IF(P30<=O30,"Yes","No"),"N/A") -> N/A | R30: =IF(AND(I30="Yes",L30=""),Dashboard!$B$2-K30,"")
A31: PV-2026-0030 | B31: 45941 | C31: CardioStat | D31: Gastrointestinal disorders | E31: Diarrhoea | F31: Non-serious | G31: Germany | H31: Healthcare Professional | I31: No | M31: =IF(AND(K31<>"",L31<>""),L31-K31,"") | N31: 45981 | O31: =IF(F31="Serious",15,"N/A") -> N/A | P31: =N31-B31 -> 40 | Q31: =IF(F31="Serious",IF(P31<=O31,"Yes","No"),"N/A") -> N/A | R31: =IF(AND(I31="Yes",L31=""),Dashboard!$B$2-K31,"")
A32: PV-2026-0031 | B32: 46095 | C32: OncoRelief | D32: Gastrointestinal disorders | E32: Nausea | F32: Serious | G32: Canada | H32: Pharmacist | I32: Yes | J32: MedDRA Coding Query | K32: 46105 | L32: 46119 | M32: =IF(AND(K32<>"",L32<>""),L32-K32,"") -> 14 | N32: 46102 | O32: =IF(F32="Serious",15,"N/A") -> 15 | P32: =N32-B32 -> 7 | Q32: =IF(F32="Serious",IF(P32<=O32,"Yes","No"),"N/A") -> Yes | R32: =IF(AND(I32="Yes",L32=""),Dashboard!$B$2-K32,"")
A33: PV-2026-0032 | B33: 45698 | C33: NeuroCalm | D33: Immune system disorders | E33: Hypersensitivity | F33: Non-serious | G33: USA | H33: Consumer | I33: No | M33: =IF(AND(K33<>"",L33<>""),L33-K33,"") | N33: 45742 | O33: =IF(F33="Serious",15,"N/A") -> N/A | P33: =N33-B33 -> 44 | Q33: =IF(F33="Serious",IF(P33<=O33,"Yes","No"),"N/A") -> N/A | R33: =IF(AND(I33="Yes",L33=""),Dashboard!$B$2-K33,"")
A34: PV-2026-0033 | B34: 45816 | C34: DiabeCare | D34: Nervous system disorders | E34: Headache | F34: Non-serious | G34: India | H34: Consumer | I34: Yes | J34: Causality Assessment | K34: 45820 | L34: 45846 | M34: =IF(AND(K34<>"",L34<>""),L34-K34,"") -> 26 | N34: 45827 | O34: =IF(F34="Serious",15,"N/A") -> N/A | P34: =N34-B34 -> 11 | Q34: =IF(F34="Serious",IF(P34<=O34,"Yes","No"),"N/A") -> N/A | R34: =IF(AND(I34="Yes",L34=""),Dashboard!$B$2-K34,"")
A35: PV-2026-0034 | B35: 46049 | C35: CardioStat | D35: Investigations | E35: Blood glucose increased | F35: Serious | G35: Canada | H35: Healthcare Professional | I35: No | M35: =IF(AND(K35<>"",L35<>""),L35-K35,"") | N35: 46068 | O35: =IF(F35="Serious",15,"N/A") -> 15 | P35: =N35-B35 -> 19 | Q35: =IF(F35="Serious",IF(P35<=O35,"Yes","No"),"N/A") -> No | R35: =IF(AND(I35="Yes",L35=""),Dashboard!$B$2-K35,"")
A36: PV-2026-0035 | B36: 45682 | C36: DiabeCare | D36: General disorders and administration site conditions | E36: Fatigue | F36: Non-serious | G36: India | H36: Consumer | I36: Yes | J36: Follow-up Required | K36: 45689 | L36: 45718 | M36: =IF(AND(K36<>"",L36<>""),L36-K36,"") -> 29 | N36: 45708 | O36: =IF(F36="Serious",15,"N/A") -> N/A | P36: =N36-B36 -> 26 | Q36: =IF(F36="Serious",IF(P36<=O36,"Yes","No"),"N/A") -> N/A | R36: =IF(AND(I36="Yes",L36=""),Dashboard!$B$2-K36,"")
A37: PV-2026-0036 | B37: 45686 | C37: CardioStat | D37: Cardiac disorders | E37: Tachycardia | F37: Non-serious | G37: Australia | H37: Healthcare Professional | I37: Yes | J37: MedDRA Coding Query | K37: 45692 | L37: 45731 | M37: =IF(AND(K37<>"",L37<>""),L37-K37,"") -> 39 | N37: 45698 | O37: =IF(F37="Serious",15,"N/A") -> N/A | P37: =N37-B37 -> 12 | Q37: =IF(F37="Serious",IF(P37<=O37,"Yes","No"),"N/A") -> N/A | R37: =IF(AND(I37="Yes",L37=""),Dashboard!$B$2-K37,"")
A38: PV-2026-0037 | B38: 46052 | C38: OncoRelief | D38: Immune system disorders | E38: Anaphylactic reaction | F38: Serious | G38: USA | H38: Consumer | I38: No | M38: =IF(AND(K38<>"",L38<>""),L38-K38,"") | N38: 46065 | O38: =IF(F38="Serious",15,"N/A") -> 15 | P38: =N38-B38 -> 13 | Q38: =IF(F38="Serious",IF(P38<=O38,"Yes","No"),"N/A") -> Yes | R38: =IF(AND(I38="Yes",L38=""),Dashboard!$B$2-K38,"")
A39: PV-2026-0038 | B39: 45859 | C39: NeuroCalm | D39: General disorders and administration site conditions | E39: Pyrexia | F39: Non-serious | G39: Canada | H39: Consumer | I39: No | M39: =IF(AND(K39<>"",L39<>""),L39-K39,"") | N39: 45871 | O39: =IF(F39="Serious",15,"N/A") -> N/A | P39: =N39-B39 -> 12 | Q39: =IF(F39="Serious",IF(P39<=O39,"Yes","No"),"N/A") -> N/A | R39: =IF(AND(I39="Yes",L39=""),Dashboard!$B$2-K39,"")
A40: PV-2026-0039 | B40: 45965 | C40: OncoRelief | D40: Cardiac disorders | E40: Palpitations | F40: Non-serious | G40: Germany | H40: Consumer | I40: Yes | J40: Source Document Discrepancy | K40: 45972 | L40: 46004 | M40: =IF(AND(K40<>"",L40<>""),L40-K40,"") -> 32 | N40: 46009 | O40: =IF(F40="Serious",15,"N/A") -> N/A | P40: =N40-B40 -> 44 | Q40: =IF(F40="Serious",IF(P40<=O40,"Yes","No"),"N/A") -> N/A | R40: =IF(AND(I40="Yes",L40=""),Dashboard!$B$2-K40,"")
...

Sheet Dashboard
A1: PV Case Query & MedDRA Coding Analytics Dashboard
A2: Report As Of: | B2: 46214
A4: Total Cases | C4: % Serious Cases | E4: Queries Raised
A5: =COUNTA('Raw Data'!A2:A401) -> 400 | C5: =COUNTIF('Raw Data'!F2:F401,"Serious")/COUNTA('Raw Data'!A2:A401) -> 0.2975 | E5: =COUNTIF('Raw Data'!I2:I401,"Yes") -> 242
A7: Avg Query Turnaround (days) | C7: % Queries Closed | E7: On-Time Submission Rate (Serious)
A8: =AVERAGEIF('Raw Data'!M2:M401,">=0") -> 17.430851 | C8: =COUNT('Raw Data'!M2:M401)/COUNTIF('Raw Data'!I2:I401,"Yes") -> 0.7768595 | E8: =COUNTIFS('Raw Data'!F2:F401,"Serious",'Raw Data'!Q2:Q401,"Yes")/COUNTIF('Raw Data'!F2:F401,"Serious") -> 0.86554622
A11: Case Volume by Month | D11: MedDRA SOC Distribution
A12: Month | B12: Cases | D12: System Organ Class | E12: Cases
A13: 45658 | B13: =COUNTIFS('Raw Data'!B2:B401,">="&A13,'Raw Data'!B2:B401,"<"&DATE(2025,2,1)) -> 26 | D13: Gastrointestinal disorders | E13: =COUNTIF('Raw Data'!D2:D401,"Gastrointestinal disorders") -> 43
A14: 45689 | B14: =COUNTIFS('Raw Data'!B2:B401,">="&A14,'Raw Data'!B2:B401,"<"&DATE(2025,3,1)) -> 23 | D14: Skin and subcutaneous tissue disorders | E14: =COUNTIF('Raw Data'!D2:D401,"Skin and subcutaneous tissue disorders") -> 41
A15: 45717 | B15: =COUNTIFS('Raw Data'!B2:B401,">="&A15,'Raw Data'!B2:B401,"<"&DATE(2025,4,1)) -> 22 | D15: Nervous system disorders | E15: =COUNTIF('Raw Data'!D2:D401,"Nervous system disorders") -> 34
A16: 45748 | B16: =COUNTIFS('Raw Data'!B2:B401,">="&A16,'Raw Data'!B2:B401,"<"&DATE(2025,5,1)) -> 20 | D16: Immune system disorders | E16: =COUNTIF('Raw Data'!D2:D401,"Immune system disorders") -> 47
A17: 45778 | B17: =COUNTIFS('Raw Data'!B2:B401,">="&A17,'Raw Data'!B2:B401,"<"&DATE(2025,6,1)) -> 26 | D17: Cardiac disorders | E17: =COUNTIF('Raw Data'!D2:D401,"Cardiac disorders") -> 42
A18: 45809 | B18: =COUNTIFS('Raw Data'!B2:B401,">="&A18,'Raw Data'!B2:B401,"<"&DATE(2025,7,1)) -> 19 | D18: Injury, poisoning and procedural complications | E18: =COUNTIF('Raw Data'!D2:D401,"Injury, poisoning and procedural complications") -> 27
A19: 45839 | B19: =COUNTIFS('Raw Data'!B2:B401,">="&A19,'Raw Data'!B2:B401,"<"&DATE(2025,8,1)) -> 20 | D19: General disorders and administration site conditions | E19: =COUNTIF('Raw Data'!D2:D401,"General disorders and administration site conditions") -> 48
A20: 45870 | B20: =COUNTIFS('Raw Data'!B2:B401,">="&A20,'Raw Data'!B2:B401,"<"&DATE(2025,9,1)) -> 19 | D20: Investigations | E20: =COUNTIF('Raw Data'!D2:D401,"Investigations") -> 40
A21: 45901 | B21: =COUNTIFS('Raw Data'!B2:B401,">="&A21,'Raw Data'!B2:B401,"<"&DATE(2025,10,1)) -> 14 | D21: Psychiatric disorders | E21: =COUNTIF('Raw Data'!D2:D401,"Psychiatric disorders") -> 47
A22: 45931 | B22: =COUNTIFS('Raw Data'!B2:B401,">="&A22,'Raw Data'!B2:B401,"<"&DATE(2025,11,1)) -> 26 | D22: Renal and urinary disorders | E22: =COUNTIF('Raw Data'!D2:D401,"Renal and urinary disorders") -> 31
A23: 45962 | B23: =COUNTIFS('Raw Data'!B2:B401,">="&A23,'Raw Data'!B2:B401,"<"&DATE(2025,12,1)) -> 23
A24: 45992 | B24: =COUNTIFS('Raw Data'!B2:B401,">="&A24,'Raw Data'!B2:B401,"<"&DATE(2026,1,1)) -> 31
A25: Query Type Distribution | B25: =COUNTIFS('Raw Data'!B2:B401,">="&A25,'Raw Data'!B2:B401,"<"&DATE(2026,2,1)) -> 0 | D25: Query Turnaround Time (Closed Queries)
A26: Query Type | B26: Count | D26: Turnaround Bucket | E26: Count
A27: Missing Information | B27: =COUNTIF('Raw Data'!J2:J401,"Missing Information") -> 34 | D27: 0-7 days | E27: =COUNTIFS('Raw Data'!M2:M401,">="&0,'Raw Data'!M2:M401,"<="&7) -> 33
A28: Data Inconsistency | B28: =COUNTIF('Raw Data'!J2:J401,"Data Inconsistency") -> 39 | D28: 8-15 days | E28: =COUNTIFS('Raw Data'!M2:M401,">="&8,'Raw Data'!M2:M401,"<="&15) -> 56
A29: MedDRA Coding Query | B29: =COUNTIF('Raw Data'!J2:J401,"MedDRA Coding Query") -> 49 | D29: 16-30 days | E29: =COUNTIFS('Raw Data'!M2:M401,">="&16,'Raw Data'!M2:M401,"<="&30) -> 72
A30: Causality Assessment | B30: =COUNTIF('Raw Data'!J2:J401,"Causality Assessment") -> 47 | D30: 30+ days | E30: =COUNTIFS('Raw Data'!M2:M401,">="&31) -> 27
A31: Follow-up Required | B31: =COUNTIF('Raw Data'!J2:J401,"Follow-up Required") -> 31
A32: Source Document Discrepancy | B32: =COUNTIF('Raw Data'!J2:J401,"Source Document Discrepancy") -> 42
A33: Open Query Backlog Aging | D33: Seriousness Breakdown
A34: Aging Bucket | B34: Count | D34: Seriousness | E34: Count
A35: 0-7 days | B35: =COUNTIFS('Raw Data'!R2:R401,">="&0,'Raw Data'!R2:R401,"<="&7) -> 1 | D35: Serious | E35: =COUNTIF('Raw Data'!F2:F401,"Serious") -> 119
A36: 8-15 days | B36: =COUNTIFS('Raw Data'!R2:R401,">="&8,'Raw Data'!R2:R401,"<="&15) -> 1 | D36: Non-serious | E36: =COUNTIF('Raw Data'!F2:F401,"Non-serious") -> 281
A37: 16-30 days | B37: =COUNTIFS('Raw Data'!R2:R401,">="&16,'Raw Data'!R2:R401,"<="&30) -> 2
A38: 30+ days | B38: =COUNTIFS('Raw Data'!R2:R401,">="&31) -> 50
